{
  "Header": {
    "Original": "CVE-2021-3281 (In Django 2.2 before 2.2.18, 3.0 before 3.0.12, and 3.1 before 3.1.6,  ...)",
    "Line": 117670,
    "ID": "CVE-2021-3281",
    "Description": "(In Django 2.2 before 2.2.18, 3.0 before 3.0.12, and 3.1 before 3.1.6,  ...)"
  },
  "Annotations": [
    {
      "Original": "{DLA-2540-1}",
      "Line": 117671,
      "Type": "xref",
      "Bugs": [
        "DLA-2540-1"
      ]
    },
    {
      "Original": "- python-django 2:2.2.18-1 (bug #981562)",
      "Line": 117672,
      "Type": "package",
      "Package": "python-django",
      "Kind": "fixed",
      "Version": "2:2.2.18-1",
      "BugNo": 981562
    },
    {
      "Original": "[buster] - python-django \u003cno-dsa\u003e (Minor issue)",
      "Line": 117673,
      "Type": "package",
      "Release": "buster",
      "Package": "python-django",
      "Kind": "no-dsa",
      "Description": "Minor issue"
    },
    {
      "Original": "NOTE: https://www.djangoproject.com/weblog/2021/feb/01/security-releases/",
      "Line": 117674,
      "Type": "NOTE",
      "Description": "https://www.djangoproject.com/weblog/2021/feb/01/security-releases/"
    },
    {
      "Original": "NOTE: https://github.com/django/django/commit/05413afa8c18cdb978fcdf470e09f7a12b234a23 (master)",
      "Line": 117675,
      "Type": "NOTE",
      "Description": "https://github.com/django/django/commit/05413afa8c18cdb978fcdf470e09f7a12b234a23 (master)"
    },
    {
      "Original": "NOTE: https://github.com/django/django/commit/21e7622dec1f8612c85c2fc37fe8efbfd3311e37 (2.2.18)",
      "Line": 117676,
      "Type": "NOTE",
      "Description": "https://github.com/django/django/commit/21e7622dec1f8612c85c2fc37fe8efbfd3311e37 (2.2.18)"
    }
  ]
}